<?xml version="1.0" encoding="UTF-8"?>
<!-- Generated by org.testng.reporters.JUnitReportReporter -->
<testsuite hostname="LGDN14479" failures="0" tests="1" name="test_case.TC001_Verify_user_can_create_new_article_with_valid_information" time="0.610" errors="1" timestamp="29 Jan 2018 09:41:13 GMT" skipped="0">
  <testcase classname="test_case.TC001_Verify_user_can_create_new_article_with_valid_information" name="login" time="0.610">
    <error message="
Data provider mismatch
Method: login([Parameter{index=0, type=java.lang.String, declaredAnnotations=[]}, Parameter{index=1, type=java.lang.String, declaredAnnotations=[]}, Parameter{index=2, type=java.lang.String, declaredAnnotations=[]}, Parameter{index=3, type=java.lang.String, declaredAnnotations=[]}])
Arguments: [(java.lang.String) tomnick,(java.lang.String) 12345678,(java.lang.String) Test Article 1]" type="org.testng.internal.reflect.MethodMatcherException">
      <![CDATA[org.testng.internal.reflect.MethodMatcherException: Data provider mismatchMethod: login([Parameter{index=0, type=java.lang.String, declaredAnnotations=[]}, Parameter{index=1, type=java.lang.String, declaredAnnotations=[]}, Parameter{index=2, type=java.lang.String, declaredAnnotations=[]}, Parameter{index=3, type=java.lang.String, declaredAnnotations=[]}])Arguments: [(java.lang.String) tomnick,(java.lang.String) 12345678,(java.lang.String) Test Article 1]at org.testng.internal.reflect.DataProviderMethodMatcher.getConformingArguments(DataProviderMethodMatcher.java:45)at org.testng.internal.Parameters.injectParameters(Parameters.java:796)at org.testng.internal.Invoker.invokeTestMethods(Invoker.java:973)at org.testng.internal.TestMethodWorker.invokeTestMethods(TestMethodWorker.java:125)at org.testng.internal.TestMethodWorker.run(TestMethodWorker.java:109)at org.testng.TestRunner.privateRun(TestRunner.java:648)at org.testng.TestRunner.run(TestRunner.java:505)at org.testng.SuiteRunner.runTest(SuiteRunner.java:455)at org.testng.SuiteRunner.runSequentially(SuiteRunner.java:450)at org.testng.SuiteRunner.privateRun(SuiteRunner.java:415)at org.testng.SuiteRunner.run(SuiteRunner.java:364)at org.testng.SuiteRunnerWorker.runSuite(SuiteRunnerWorker.java:52)at org.testng.SuiteRunnerWorker.run(SuiteRunnerWorker.java:84)at org.testng.TestNG.runSuitesSequentially(TestNG.java:1187)at org.testng.TestNG.runSuitesLocally(TestNG.java:1116)at org.testng.TestNG.runSuites(TestNG.java:1028)at org.testng.TestNG.run(TestNG.java:996)at org.testng.remote.AbstractRemoteTestNG.run(AbstractRemoteTestNG.java:114)at org.testng.remote.RemoteTestNG.initAndRun(RemoteTestNG.java:251)at org.testng.remote.RemoteTestNG.main(RemoteTestNG.java:77)]]>
    </error>
  </testcase> <!-- login -->
</testsuite> <!-- test_case.TC001_Verify_user_can_create_new_article_with_valid_information -->
